<mujoco model="g1_53dof">
    <compiler angle="radian" meshdir="meshes"/>


    <default>
        <!-- 默认阻尼系数/转子惯量/摩擦损耗 -->
        <joint damping="0.001" armature="0.01" frictionloss="0.1"/>
    </default>
    <asset>
        <mesh name="pelvis" file="pelvis.STL"/>
        <mesh name="pelvis_contour_link" file="pelvis_contour_link.STL"/>
        <mesh name="left_hip_pitch_link" file="left_hip_pitch_link.STL"/>
        <mesh name="left_hip_roll_link" file="left_hip_roll_link.STL"/>
        <mesh name="left_hip_yaw_link" file="left_hip_yaw_link.STL"/>
        <mesh name="left_knee_link" file="left_knee_link.STL"/>
        <mesh name="left_ankle_pitch_link" file="left_ankle_pitch_link.STL"/>
        <mesh name="left_ankle_roll_link" file="left_ankle_roll_link.STL"/>
        <mesh name="right_hip_pitch_link" file="right_hip_pitch_link.STL"/>
        <mesh name="right_hip_roll_link" file="right_hip_roll_link.STL"/>
        <mesh name="right_hip_yaw_link" file="right_hip_yaw_link.STL"/>
        <mesh name="right_knee_link" file="right_knee_link.STL"/>
        <mesh name="right_ankle_pitch_link" file="right_ankle_pitch_link.STL"/>
        <mesh name="right_ankle_roll_link" file="right_ankle_roll_link.STL"/>
        <mesh name="waist_yaw_link" file="waist_yaw_link.STL"/>
        <mesh name="waist_roll_link" file="waist_roll_link.STL"/>
        <mesh name="torso_link" file="torso_link.STL"/>
        <mesh name="logo_link" file="logo_link.STL"/>
        <mesh name="head_link" file="head_link.STL"/>
        <mesh name="waist_support_link" file="waist_support_link.STL"/>
        <mesh name="left_shoulder_pitch_link" file="left_shoulder_pitch_link.STL"/>
        <mesh name="left_shoulder_roll_link" file="left_shoulder_roll_link.STL"/>
        <mesh name="left_shoulder_yaw_link" file="left_shoulder_yaw_link.STL"/>
        <mesh name="left_elbow_link" file="left_elbow_link.STL"/>
        <mesh name="left_wrist_roll_link" file="left_wrist_roll_link.STL"/>
        <mesh name="left_wrist_pitch_link" file="left_wrist_pitch_link.STL"/>
        <mesh name="left_wrist_yaw_link" file="left_wrist_yaw_link.STL"/>
        <mesh name="left_hand_palm_link" file="left_hand_palm_link.STL"/>
        <!--        <mesh name="left_rubber_hand" file="left_rubber_hand.STL"/>-->
        <mesh name="left_hand_thumb_0_link" file="left_hand_thumb_0_link.STL"/>
        <mesh name="left_hand_thumb_1_link" file="left_hand_thumb_1_link.STL"/>
        <mesh name="left_hand_thumb_2_link" file="left_hand_thumb_2_link.STL"/>
        <mesh name="left_hand_middle_0_link" file="left_hand_middle_0_link.STL"/>
        <mesh name="left_hand_middle_1_link" file="left_hand_middle_1_link.STL"/>
        <mesh name="left_hand_index_0_link" file="left_hand_index_0_link.STL"/>
        <mesh name="left_hand_index_1_link" file="left_hand_index_1_link.STL"/>
        <mesh name="right_shoulder_pitch_link" file="right_shoulder_pitch_link.STL"/>
        <mesh name="right_shoulder_roll_link" file="right_shoulder_roll_link.STL"/>
        <mesh name="right_shoulder_yaw_link" file="right_shoulder_yaw_link.STL"/>
        <mesh name="right_elbow_link" file="right_elbow_link.STL"/>
        <mesh name="right_wrist_roll_link" file="right_wrist_roll_link.STL"/>
        <mesh name="right_wrist_pitch_link" file="right_wrist_pitch_link.STL"/>
        <mesh name="right_wrist_yaw_link" file="right_wrist_yaw_link.STL"/>
        <!--        <mesh name="right_rubber_hand" file="right_rubber_hand.STL"/>-->
        <mesh name="right_hand_palm_link" file="right_hand_palm_link.STL"/>
        <!--右手-->
        <mesh name="right_hand_thumb_0_link" file="right_hand_thumb_0_link.STL"/>
        <mesh name="right_hand_thumb_1_link" file="right_hand_thumb_1_link.STL"/>
        <mesh name="right_hand_thumb_2_link" file="right_hand_thumb_2_link.STL"/>
        <mesh name="right_hand_middle_0_link" file="right_hand_middle_0_link.STL"/>
        <mesh name="right_hand_middle_1_link" file="right_hand_middle_1_link.STL"/>
        <mesh name="right_hand_index_0_link" file="right_hand_index_0_link.STL"/>
        <mesh name="right_hand_index_1_link" file="right_hand_index_1_link.STL"/>

        <mesh name="R_hand_base_link" file="R_hand_base_link.STL"/>
        <mesh name="Link11_R" file="Link11_R.STL"/>
        <mesh name="Link12_R" file="Link12_R.STL"/>
        <mesh name="Link13_R" file="Link13_R.STL"/>
        <mesh name="Link14_R" file="Link14_R.STL"/>
        <mesh name="Link15_R" file="Link15_R.STL"/>
        <mesh name="Link16_R" file="Link16_R.STL"/>
        <mesh name="Link17_R" file="Link17_R.STL"/>
        <mesh name="Link18_R" file="Link18_R.STL"/>
        <mesh name="Link19_R" file="Link19_R.STL"/>
        <mesh name="Link20_R" file="Link20_R.STL"/>
        <mesh name="Link21_R" file="Link21_R.STL"/>
        <mesh name="Link22_R" file="Link22_R.STL"/>

        <mesh name="L_hand_base_link" file="L_hand_base_link.STL"/>
        <mesh name="Link11_L" file="Link11_L.STL"/>
        <mesh name="Link12_L" file="Link12_L.STL"/>
        <mesh name="Link13_L" file="Link13_L.STL"/>
        <mesh name="Link14_L" file="Link14_L.STL"/>
        <mesh name="Link15_L" file="Link15_L.STL"/>
        <mesh name="Link16_L" file="Link16_L.STL"/>
        <mesh name="Link17_L" file="Link17_L.STL"/>
        <mesh name="Link18_L" file="Link18_L.STL"/>
        <mesh name="Link19_L" file="Link19_L.STL"/>
        <mesh name="Link20_L" file="Link20_L.STL"/>
        <mesh name="Link21_L" file="Link21_L.STL"/>
        <mesh name="Link22_L" file="Link22_L.STL"/>


    </asset>

    <worldbody>
        <body name="pelvis" pos="0.80 -1.55 0.763">
<!--        <body name="pelvis" pos="0 0 0.763">-->
            <inertial pos="0 0 -0.07605" quat="1 0 -0.000399148 0" mass="3.813"
                      diaginertia="0.010549 0.0093089 0.0079184"/>
            <joint name="floating_base_joint" type="free" limited="false" actuatorfrclimited="false"/>
            <geom type="mesh" contype="0" conaffinity="0" group="1" density="0" rgba="0.2 0.2 0.2 1" mesh="pelvis"/>
            <geom type="mesh" contype="0" conaffinity="0" group="1" density="0" rgba="0.7 0.7 0.7 1"
                  mesh="pelvis_contour_link"/>
            <geom type="mesh" rgba="0.7 0.7 0.7 1" mesh="pelvis_contour_link"/>
            <site name="imu_in_pelvis" size="0.01" pos="0.04525 0 -0.08339"/>
            <body name="left_hip_pitch_link" pos="0 0.064452 -0.1027">
                <inertial pos="0.002741 0.047791 -0.02606" quat="0.954862 0.293964 0.0302556 0.030122" mass="1.35"
                          diaginertia="0.00181517 0.00153422 0.00116212"/>
                <joint name="left_hip_pitch_joint" pos="0 0 0" axis="0 1 0" range="-2.5307 2.8798"
                       actuatorfrcrange="-88 88"/>
                <geom type="mesh" contype="0" conaffinity="0" group="1" density="0" rgba="0.2 0.2 0.2 1"
                      mesh="left_hip_pitch_link"/>
                <geom type="mesh" rgba="0.2 0.2 0.2 1" mesh="left_hip_pitch_link"/>
                <body name="left_hip_roll_link" pos="0 0.052 -0.030465" quat="0.996179 0 -0.0873386 0">
                    <inertial pos="0.029812 -0.001045 -0.087934" quat="0.977808 -1.97119e-05 0.205576 -0.0403793"
                              mass="1.52" diaginertia="0.00254986 0.00241169 0.00148755"/>
                    <joint name="left_hip_roll_joint" pos="0 0 0" axis="1 0 0" range="-0.5236 2.9671"
                           actuatorfrcrange="-88 88"/>
                    <geom type="mesh" contype="0" conaffinity="0" group="1" density="0" rgba="0.7 0.7 0.7 1"
                          mesh="left_hip_roll_link"/>
                    <geom type="mesh" rgba="0.7 0.7 0.7 1" mesh="left_hip_roll_link"/>
                    <body name="left_hip_yaw_link" pos="0.025001 0 -0.12412">
                        <inertial pos="-0.057709 -0.010981 -0.15078" quat="0.600598 0.15832 0.223482 0.751181"
                                  mass="1.702" diaginertia="0.00776166 0.00717575 0.00160139"/>
                        <joint name="left_hip_yaw_joint" pos="0 0 0" axis="0 0 1" range="-2.7576 2.7576"
                               actuatorfrcrange="-88 88"/>
                        <geom type="mesh" contype="0" conaffinity="0" group="1" density="0" rgba="0.7 0.7 0.7 1"
                              mesh="left_hip_yaw_link"/>
                        <geom type="mesh" rgba="0.7 0.7 0.7 1" mesh="left_hip_yaw_link"/>
                        <body name="left_knee_link" pos="-0.078273 0.0021489 -0.17734" quat="0.996179 0 0.0873386 0">
                            <inertial pos="0.005457 0.003964 -0.12074" quat="0.923418 -0.0327699 0.0158246 0.382067"
                                      mass="1.932" diaginertia="0.0113804 0.0112778 0.00146458"/>
                            <joint name="left_knee_joint" pos="0 0 0" axis="0 1 0" range="-0.087267 2.8798"
                                   actuatorfrcrange="-139 139"/>
                            <geom type="mesh" contype="0" conaffinity="0" group="1" density="0" rgba="0.7 0.7 0.7 1"
                                  mesh="left_knee_link"/>
                            <geom type="mesh" rgba="0.7 0.7 0.7 1" mesh="left_knee_link"/>
                            <body name="left_ankle_pitch_link" pos="0 -9.4445e-05 -0.30001">
                                <inertial pos="-0.007269 0 0.011137" quat="0.603053 0.369225 0.369225 0.603053"
                                          mass="0.074" diaginertia="1.89e-05 1.40805e-05 6.9195e-06"/>
                                <joint name="left_ankle_pitch_joint" pos="0 0 0" axis="0 1 0" range="-0.87267 0.5236"
                                       actuatorfrcrange="-50 50"/>
                                <geom type="mesh" contype="0" conaffinity="0" group="1" density="0" rgba="0.7 0.7 0.7 1"
                                      mesh="left_ankle_pitch_link"/>
                                <geom type="mesh" rgba="0.7 0.7 0.7 1" mesh="left_ankle_pitch_link"/>
                                <body name="left_ankle_roll_link" pos="0 0 -0.017558">
                                    <inertial pos="0.026505 0 -0.016425"
                                              quat="-0.000481092 0.728482 -0.000618967 0.685065" mass="0.608"
                                              diaginertia="0.00167218 0.0016161 0.000217621"/>
                                    <joint name="left_ankle_roll_joint" pos="0 0 0" axis="1 0 0" range="-0.2618 0.2618"
                                           actuatorfrcrange="-50 50"/>
                                    <geom type="mesh" contype="0" conaffinity="0" group="1" density="0"
                                          rgba="0.2 0.2 0.2 1" mesh="left_ankle_roll_link"/>
                                    <geom size="0.005" pos="-0.05 0.025 -0.03" rgba="0.2 0.2 0.2 1"/>
                                    <geom size="0.005" pos="-0.05 -0.025 -0.03" rgba="0.2 0.2 0.2 1"/>
                                    <geom size="0.005" pos="0.12 0.03 -0.03" rgba="0.2 0.2 0.2 1"/>
                                    <geom size="0.005" pos="0.12 -0.03 -0.03" rgba="0.2 0.2 0.2 1"/>
                                </body>
                            </body>
                        </body>
                    </body>
                </body>
            </body>
            <body name="right_hip_pitch_link" pos="0 -0.064452 -0.1027">
                <inertial pos="0.002741 -0.047791 -0.02606" quat="0.954862 -0.293964 0.0302556 -0.030122" mass="1.35"
                          diaginertia="0.00181517 0.00153422 0.00116212"/>
                <joint name="right_hip_pitch_joint" pos="0 0 0" axis="0 1 0" range="-2.5307 2.8798"
                       actuatorfrcrange="-88 88"/>
                <geom type="mesh" contype="0" conaffinity="0" group="1" density="0" rgba="0.2 0.2 0.2 1"
                      mesh="right_hip_pitch_link"/>
                <geom type="mesh" rgba="0.2 0.2 0.2 1" mesh="right_hip_pitch_link"/>
                <body name="right_hip_roll_link" pos="0 -0.052 -0.030465" quat="0.996179 0 -0.0873386 0">
                    <inertial pos="0.029812 0.001045 -0.087934" quat="0.977808 1.97119e-05 0.205576 0.0403793"
                              mass="1.52" diaginertia="0.00254986 0.00241169 0.00148755"/>
                    <joint name="right_hip_roll_joint" pos="0 0 0" axis="1 0 0" range="-2.9671 0.5236"
                           actuatorfrcrange="-88 88"/>
                    <geom type="mesh" contype="0" conaffinity="0" group="1" density="0" rgba="0.7 0.7 0.7 1"
                          mesh="right_hip_roll_link"/>
                    <geom type="mesh" rgba="0.7 0.7 0.7 1" mesh="right_hip_roll_link"/>
                    <body name="right_hip_yaw_link" pos="0.025001 0 -0.12412">
                        <inertial pos="-0.057709 0.010981 -0.15078" quat="0.751181 0.223482 0.15832 0.600598"
                                  mass="1.702" diaginertia="0.00776166 0.00717575 0.00160139"/>
                        <joint name="right_hip_yaw_joint" pos="0 0 0" axis="0 0 1" range="-2.7576 2.7576"
                               actuatorfrcrange="-88 88"/>
                        <geom type="mesh" contype="0" conaffinity="0" group="1" density="0" rgba="0.7 0.7 0.7 1"
                              mesh="right_hip_yaw_link"/>
                        <geom type="mesh" rgba="0.7 0.7 0.7 1" mesh="right_hip_yaw_link"/>
                        <body name="right_knee_link" pos="-0.078273 -0.0021489 -0.17734" quat="0.996179 0 0.0873386 0">
                            <inertial pos="0.005457 -0.003964 -0.12074" quat="0.923439 0.0345276 0.0116333 -0.382012"
                                      mass="1.932" diaginertia="0.011374 0.0112843 0.00146452"/>
                            <joint name="right_knee_joint" pos="0 0 0" axis="0 1 0" range="-0.087267 2.8798"
                                   actuatorfrcrange="-139 139"/>
                            <geom type="mesh" contype="0" conaffinity="0" group="1" density="0" rgba="0.7 0.7 0.7 1"
                                  mesh="right_knee_link"/>
                            <geom type="mesh" rgba="0.7 0.7 0.7 1" mesh="right_knee_link"/>
                            <body name="right_ankle_pitch_link" pos="0 9.4445e-05 -0.30001">
                                <inertial pos="-0.007269 0 0.011137" quat="0.603053 0.369225 0.369225 0.603053"
                                          mass="0.074" diaginertia="1.89e-05 1.40805e-05 6.9195e-06"/>
                                <joint name="right_ankle_pitch_joint" pos="0 0 0" axis="0 1 0" range="-0.87267 0.5236"
                                       actuatorfrcrange="-50 50"/>
                                <geom type="mesh" contype="0" conaffinity="0" group="1" density="0" rgba="0.7 0.7 0.7 1"
                                      mesh="right_ankle_pitch_link"/>
                                <geom type="mesh" rgba="0.7 0.7 0.7 1" mesh="right_ankle_pitch_link"/>
                                <body name="right_ankle_roll_link" pos="0 0 -0.017558">
                                    <inertial pos="0.026505 0 -0.016425"
                                              quat="0.000481092 0.728482 0.000618967 0.685065" mass="0.608"
                                              diaginertia="0.00167218 0.0016161 0.000217621"/>
                                    <joint name="right_ankle_roll_joint" pos="0 0 0" axis="1 0 0" range="-0.2618 0.2618"
                                           actuatorfrcrange="-50 50"/>
                                    <geom type="mesh" contype="0" conaffinity="0" group="1" density="0"
                                          rgba="0.2 0.2 0.2 1" mesh="right_ankle_roll_link"/>
                                    <geom size="0.005" pos="-0.05 0.025 -0.03" rgba="0.2 0.2 0.2 1"/>
                                    <geom size="0.005" pos="-0.05 -0.025 -0.03" rgba="0.2 0.2 0.2 1"/>
                                    <geom size="0.005" pos="0.12 0.03 -0.03" rgba="0.2 0.2 0.2 1"/>
                                    <geom size="0.005" pos="0.12 -0.03 -0.03" rgba="0.2 0.2 0.2 1"/>
                                </body>
                            </body>
                        </body>
                    </body>
                </body>
            </body>
            <body name="waist_yaw_link">
                <inertial pos="0.003964 0 0.018769" quat="-0.0178291 0.628464 0.0282471 0.777121" mass="0.244"
                          diaginertia="0.000158561 0.000124229 9.67669e-05"/>
                <joint name="waist_yaw_joint" pos="0 0 0" axis="0 0 1" range="-2.618 2.618" actuatorfrcrange="-88 88"/>
                <geom type="mesh" contype="0" conaffinity="0" group="1" density="0" rgba="0.7 0.7 0.7 1"
                      mesh="waist_yaw_link"/>
                <body name="waist_roll_link" pos="-0.0039635 0 0.035">
                    <inertial pos="0 -0.000236 0.010111" quat="0.99979 0.020492 0 0" mass="0.047"
                              diaginertia="7.515e-06 6.40206e-06 3.98394e-06"/>
                    <joint name="waist_roll_joint" pos="0 0 0" axis="1 0 0" range="-0.52 0.52"
                           actuatorfrcrange="-50 50"/>
                    <geom type="mesh" contype="0" conaffinity="0" group="1" density="0" rgba="0.7 0.7 0.7 1"
                          mesh="waist_roll_link"/>
                    <body name="torso_link" pos="0 0 0.019">
                        <inertial pos="0.00331658 0.000261533 0.179856"
                                  quat="0.999831 0.000376204 0.0179895 -0.00377704" mass="9.598"
                                  diaginertia="0.12407 0.111951 0.0325382"/>
                        <joint name="waist_pitch_joint" pos="0 0 0" axis="0 1 0" range="-0.52 0.52"
                               actuatorfrcrange="-50 50"/>
                        <geom type="mesh" contype="0" conaffinity="0" group="1" density="0" rgba="0.7 0.7 0.7 1"
                              mesh="torso_link"/>
                        <geom type="mesh" rgba="0.7 0.7 0.7 1" mesh="torso_link"/>
                        <geom pos="0.0039635 0 -0.054" quat="1 0 0 0" type="mesh" contype="0" conaffinity="0" group="1"
                              density="0" rgba="0.2 0.2 0.2 1" mesh="logo_link"/>
                        <geom pos="0.0039635 0 -0.054" quat="1 0 0 0" type="mesh" rgba="0.2 0.2 0.2 1"
                              mesh="logo_link"/>
                        <geom pos="0.0039635 0 -0.054" type="mesh" contype="0" conaffinity="0" group="1" density="0"
                              rgba="0.2 0.2 0.2 1" mesh="head_link"/>
                        <geom pos="0.0039635 0 -0.054" type="mesh" rgba="0.2 0.2 0.2 1" mesh="head_link"/>
                        <geom pos="0.0039635 0 -0.054" quat="1 0 0 0" type="mesh" contype="0" conaffinity="0" group="1"
                              density="0" rgba="0.7 0.7 0.7 1" mesh="waist_support_link"/>
                        <geom pos="0.0039635 0 -0.054" quat="1 0 0 0" type="mesh" rgba="0.7 0.7 0.7 1"
                              mesh="waist_support_link"/>
                        <site name="imu_in_torso" size="0.01" pos="-0.03959 -0.00224 0.13792"/>
                        <body name="left_shoulder_pitch_link" pos="0.0039563 0.10022 0.23778"
                              quat="0.990264 0.139201 1.38722e-05 -9.86868e-05">
                            <inertial pos="0 0.035892 -0.011628" quat="0.654152 0.0130458 -0.326267 0.68225"
                                      mass="0.718" diaginertia="0.000465864 0.000432842 0.000406394"/>
                            <joint name="left_shoulder_pitch_joint" pos="0 0 0" axis="0 1 0" range="-3.0892 2.6704"
                                   actuatorfrcrange="-25 25"/>
                            <geom type="mesh" contype="0" conaffinity="0" group="1" density="0" rgba="0.7 0.7 0.7 1"
                                  mesh="left_shoulder_pitch_link"/>
                            <geom size="0.03 0.025" pos="0 0.04 -0.01" quat="0.707107 0 0.707107 0" type="cylinder"
                                  rgba="0.7 0.7 0.7 1"/>
                            <body name="left_shoulder_roll_link" pos="0 0.038 -0.013831" quat="0.990268 -0.139172 0 0">
                                <inertial pos="-0.000227 0.00727 -0.063243"
                                          quat="0.701256 -0.0196223 -0.00710317 0.712604" mass="0.643"
                                          diaginertia="0.000691311 0.000618011 0.000388977"/>
                                <joint name="left_shoulder_roll_joint" pos="0 0 0" axis="1 0 0" range="-1.5882 2.2515"
                                       actuatorfrcrange="-25 25"/>
                                <geom type="mesh" contype="0" conaffinity="0" group="1" density="0" rgba="0.7 0.7 0.7 1"
                                      mesh="left_shoulder_roll_link"/>
                                <geom size="0.03 0.015" pos="-0.004 0.006 -0.053" type="cylinder" rgba="0.7 0.7 0.7 1"/>
                                <body name="left_shoulder_yaw_link" pos="0 0.00624 -0.1032">
                                    <inertial pos="0.010773 -0.002949 -0.072009"
                                              quat="0.716879 -0.0964829 -0.0679942 0.687134" mass="0.734"
                                              diaginertia="0.00106187 0.00103217 0.000400661"/>
                                    <joint name="left_shoulder_yaw_joint" pos="0 0 0" axis="0 0 1" range="-2.618 2.618"
                                           actuatorfrcrange="-25 25"/>
                                    <geom type="mesh" contype="0" conaffinity="0" group="1" density="0"
                                          rgba="0.7 0.7 0.7 1" mesh="left_shoulder_yaw_link"/>
                                    <geom type="mesh" rgba="0.7 0.7 0.7 1" mesh="left_shoulder_yaw_link"/>
                                    <body name="left_elbow_link" pos="0.015783 0 -0.080518">
                                        <inertial pos="0.064956 0.004454 -0.010062"
                                                  quat="0.541765 0.636132 0.388821 0.388129" mass="0.6"
                                                  diaginertia="0.000443035 0.000421612 0.000259353"/>
                                        <joint name="left_elbow_joint" pos="0 0 0" axis="0 1 0" range="-1.0472 2.0944"
                                               actuatorfrcrange="-25 25"/>
                                        <geom type="mesh" contype="0" conaffinity="0" group="1" density="0"
                                              rgba="0.7 0.7 0.7 1" mesh="left_elbow_link"/>
                                        <geom type="mesh" rgba="0.7 0.7 0.7 1" mesh="left_elbow_link"/>
                                        <body name="left_wrist_roll_link" pos="0.1 0.00188791 -0.01">
                                            <inertial pos="0.0171394 0.000537591 4.8864e-07"
                                                      quat="0.575338 0.411667 -0.574906 0.411094" mass="0.085445"
                                                      diaginertia="5.48211e-05 4.96646e-05 3.57798e-05"/>
                                            <joint name="left_wrist_roll_joint" pos="0 0 0" axis="1 0 0"
                                                   range="-1.97222 1.97222" actuatorfrcrange="-25 25"/>
                                            <geom type="mesh" contype="0" conaffinity="0" group="1" density="0"
                                                  rgba="0.7 0.7 0.7 1" mesh="left_wrist_roll_link"/>
                                            <geom type="mesh" rgba="0.7 0.7 0.7 1" mesh="left_wrist_roll_link"/>
                                            <body name="left_wrist_pitch_link" pos="0.038 0 0">
                                                <inertial pos="0.0229999 -0.00111685 -0.00111658"
                                                          quat="0.249998 0.661363 0.293036 0.643608" mass="0.48405"
                                                          diaginertia="0.000430353 0.000429873 0.000164648"/>
                                                <joint name="left_wrist_pitch_joint" pos="0 0 0" axis="0 1 0"
                                                       range="-1.61443 1.61443" actuatorfrcrange="-5 5"/>
                                                <geom type="mesh" contype="0" conaffinity="0" group="1" density="0"
                                                      rgba="0.7 0.7 0.7 1" mesh="left_wrist_pitch_link"/>
                                                <geom type="mesh" rgba="0.7 0.7 0.7 1" mesh="left_wrist_pitch_link"/>
                                                <body name="left_wrist_yaw_link" pos="0.046 0 0">
                                                    <inertial pos="0.0708244 0.000191745 0.00161742"
                                                              quat="0.510571 0.526295 0.468078 0.493188" mass="0.254576"
                                                              diaginertia="0.000646113 0.000559993 0.000147566"/>
                                                    <joint name="left_wrist_yaw_joint" pos="0 0 0" axis="0 0 1"
                                                           range="-1.61443 1.61443" actuatorfrcrange="-5 5"/>
                                                    <geom type="mesh" contype="0" conaffinity="0" group="1" density="0"
                                                          rgba="0.7 0.7 0.7 1" mesh="left_wrist_yaw_link"/>
                                                    <geom type="mesh" rgba="0.7 0.7 0.7 1" mesh="left_wrist_yaw_link"/>
                                                    <!--                                                    <geom pos="0.0415 0.003 0" quat="1 0 0 0" type="mesh" contype="0"-->
                                                    <!--                                                          conaffinity="0" group="1" density="0" rgba="0.7 0.7 0.7 1"-->
                                                    <!--                                                          mesh="left_hand_palm_link"/>-->
                                                    <!--                                                    <geom pos="0.0415 0.003 0" quat="1 0 0 0" type="mesh"-->
                                                    <!--                                                          rgba="0.7 0.7 0.7 1" mesh="left_hand_palm_link"/>-->
                                                    <body quat="0.707 0 0 0.707" pos="0.0415 0.003 0">
                                                        <geom type="mesh" contype="0" conaffinity="0" group="1"
                                                              density="0"
                                                              rgba="1 1 1 1" mesh="L_hand_base_link"/>
                                                        <geom type="mesh" rgba="1 1 1 1" mesh="L_hand_base_link"/>
<!--                                                        <geom size="0.004 0.075" pos="0.075 0 0"-->
<!--                                                              quat="0.707105 0 -0.707108 0" type="cylinder" contype="0"-->
<!--                                                              conaffinity="0" group="1" density="0" rgba="1 0 0 1"/>-->
<!--                                                        <geom size="0.015" pos="0.15 0 0" quat="0.707105 0 -0.707108 0"-->
<!--                                                              contype="0" conaffinity="0" group="1" density="0"-->
<!--                                                              rgba="1 0 0 1"/>-->
<!--                                                        <geom size="0.004 0.075" pos="0 0.075 0"-->
<!--                                                              quat="0.707105 0.707108 0 0" type="cylinder" contype="0"-->
<!--                                                              conaffinity="0" group="1" density="0" rgba="0 1 0 1"/>-->
<!--                                                        <geom size="0.015" pos="0 0.15 0" quat="0.707105 0.707108 0 0"-->
<!--                                                              contype="0" conaffinity="0" group="1" density="0"-->
<!--                                                              rgba="0 1 0 1"/>-->
<!--                                                        <geom size="0.004 0.075" pos="0 0 0.075" type="cylinder"-->
<!--                                                              contype="0"-->
<!--                                                              conaffinity="0" group="1" density="0" rgba="0 0 1 1"/>-->
<!--                                                        <geom size="0.015" pos="0 0 0.15" contype="0" conaffinity="0"-->
<!--                                                              group="1" density="0" rgba="0 0 1 1"/>-->
                                                        <body name="L_thumb_proximal_base"
                                                              pos="-0.01696 -0.0691 0.02045"
                                                              quat="0.499998 0.5 -0.5 0.500002">
                                                            <inertial pos="0.0048817 0.00038782 -0.00722"
                                                                      quat="0.445981 0.352284 0.495833 0.656617"
                                                                      mass="0.0018869"
                                                                      diaginertia="8.66031e-08 6.87331e-08 4.94199e-08"/>
                                                            <joint name="L_thumb_proximal_yaw_joint" pos="0 0 0"
                                                                   axis="0 0 1" range="-0.1 1.3"
                                                                   actuatorfrcrange="-1 1"/>
                                                            <geom type="mesh" contype="0" conaffinity="0" group="1"
                                                                  density="0" rgba="1 1 1 1" mesh="Link11_L"/>
                                                            <geom type="mesh" rgba="1 1 1 1" mesh="Link11_L"/>
                                                            <body name="L_thumb_proximal"
                                                                  pos="0.0099867 0.0098242 -0.0089"
                                                                  quat="0.704571 -0.704573 -0.0598169 0.0598167">
                                                                <inertial pos="0.021936 -0.01279 -0.0080386"
                                                                          quat="0.25452 0.660687 -0.251949 0.659723"
                                                                          mass="0.0066101"
                                                                          diaginertia="2.78701e-06 2.44024e-06 8.6466e-07"/>
                                                                <joint name="L_thumb_proximal_pitch_joint" pos="0 0 0"
                                                                       axis="0 0 -1" range="0 0.5"
                                                                       actuatorfrcrange="-1 1"/>
                                                                <geom type="mesh" contype="0" conaffinity="0" group="1"
                                                                      density="0" rgba="1 1 1 1" mesh="Link12_L"/>
                                                                <geom type="mesh" rgba="1 1 1 1" mesh="Link12_L"/>
                                                                <body name="L_thumb_intermediate"
                                                                      pos="0.04407 -0.034553 -0.0008">
                                                                    <inertial pos="0.0095531 0.0016282 -0.0072002"
                                                                              quat="0.30738 0.636732 -0.307526 0.636803"
                                                                              mass="0.0037844"
                                                                              diaginertia="4.6532e-07 4.48114e-07 2.45646e-07"/>
                                                                    <joint name="L_thumb_intermediate_joint" pos="0 0 0"
                                                                           axis="0 0 -1" range="0 0.8"
                                                                           actuatorfrcrange="-1 1"/>
                                                                    <geom type="mesh" contype="0" conaffinity="0"
                                                                          group="1"
                                                                          density="0" rgba="1 1 1 1" mesh="Link13_L"/>
                                                                    <geom type="mesh" rgba="1 1 1 1" mesh="Link13_L"/>
                                                                    <body name="L_thumb_distal"
                                                                          pos="0.020248 -0.010156 -0.0012">
                                                                        <inertial pos="0.0092888 -0.004953 -0.0060033"
                                                                                  quat="0.266264 0.65596 -0.262836 0.655544"
                                                                                  mass="0.003344"
                                                                                  diaginertia="2.0026e-07 1.95246e-07 8.1594e-08"/>
                                                                        <joint name="L_thumb_distal_joint" pos="0 0 0"
                                                                               axis="0 0 -1" range="0 1.2"
                                                                               actuatorfrcrange="-1 1"/>
                                                                        <geom type="mesh" contype="0" conaffinity="0"
                                                                              group="1" density="0" rgba="1 1 1 1"
                                                                              mesh="Link14_L"/>
                                                                        <geom type="mesh" rgba="1 1 1 1"
                                                                              mesh="Link14_L"/>
                                                                        <geom size="0.005" pos="0.015 -0.013 -0.004"
                                                                              contype="0" conaffinity="0" group="1"
                                                                              density="0" rgba="1 0 0 1"/>
                                                                    </body>
                                                                </body>
                                                            </body>
                                                        </body>
                                                        <body name="L_index_proximal" pos="0.00028533 -0.13653 0.032268"
                                                              quat="0.999848 -0.0174526 0 0">
                                                            <inertial pos="0.0012971 -0.011934 -0.0059998"
                                                                      quat="0.489677 0.510115 -0.489692 0.510099"
                                                                      mass="0.0042405"
                                                                      diaginertia="6.9402e-07 6.62904e-07 2.10916e-07"/>
                                                            <joint name="L_index_proximal_joint" pos="0 0 0"
                                                                   axis="0 0 -1"
                                                                   range="0 1.7" actuatorfrcrange="-1 1"/>
                                                            <geom type="mesh" contype="0" conaffinity="0" group="1"
                                                                  density="0" rgba="1 1 1 1" mesh="Link15_L"/>
                                                            <geom type="mesh" rgba="1 1 1 1" mesh="Link15_L"/>
                                                            <body name="L_index_intermediate"
                                                                  pos="-0.0024229 -0.032041 -0.001">
                                                                <inertial pos="0.0021753 -0.019567 -0.005"
                                                                          quat="0.528694 0.469555 -0.528694 0.469555"
                                                                          mass="0.0045682"
                                                                          diaginertia="7.8176e-07 7.72427e-07 8.47209e-08"/>
                                                                <joint name="L_index_intermediate_joint" pos="0 0 0"
                                                                       axis="0 0 -1" range="0 1.7"
                                                                       actuatorfrcrange="-1 1"/>
                                                                <geom type="mesh" contype="0" conaffinity="0" group="1"
                                                                      density="0" rgba="1 1 1 1" mesh="Link16_L"/>
                                                                <geom type="mesh" rgba="1 1 1 1" mesh="Link16_L"/>
                                                                <geom size="0.005" pos="-0.005 -0.04 -0.004" contype="0"
                                                                      conaffinity="0" group="1" density="0"
                                                                      rgba="0 1 0 1"/>
                                                            </body>
                                                        </body>
                                                        <body name="L_middle_proximal" pos="0.00028533 -0.1371 0.01295">
                                                            <inertial pos="0.0012971 -0.011934 -0.0059999"
                                                                      quat="0.489677 0.510115 -0.489692 0.510099"
                                                                      mass="0.0042405"
                                                                      diaginertia="6.9402e-07 6.62904e-07 2.10916e-07"/>
                                                            <joint name="L_middle_proximal_joint" pos="0 0 0"
                                                                   axis="0 0 -1"
                                                                   range="0 1.7" actuatorfrcrange="-1 1"/>
                                                            <geom type="mesh" contype="0" conaffinity="0" group="1"
                                                                  density="0" rgba="1 1 1 1" mesh="Link17_L"/>
                                                            <geom type="mesh" rgba="1 1 1 1" mesh="Link17_L"/>
                                                            <body name="L_middle_intermediate"
                                                                  pos="-0.0024229 -0.032041 -0.001">
                                                                <inertial pos="0.001921 -0.020796 -0.0049999"
                                                                          quat="0.531603 0.466115 -0.531728 0.466262"
                                                                          mass="0.0050397"
                                                                          diaginertia="9.8385e-07 9.73288e-07 9.14016e-08"/>
                                                                <joint name="L_middle_intermediate_joint" pos="0 0 0"
                                                                       axis="0 0 -1" range="0 1.7"
                                                                       actuatorfrcrange="-1 1"/>
                                                                <geom type="mesh" contype="0" conaffinity="0" group="1"
                                                                      density="0" rgba="1 1 1 1" mesh="Link18_L"/>
                                                                <geom type="mesh" rgba="1 1 1 1" mesh="Link18_L"/>
                                                                <geom size="0.005" pos="-0.005 -0.045 -0.004"
                                                                      contype="0"
                                                                      conaffinity="0" group="1" density="0"
                                                                      rgba="0 0 1 1"/>
                                                            </body>
                                                        </body>
                                                        <body name="L_ring_proximal"
                                                              pos="0.00028533 -0.13691 -0.0062872"
                                                              quat="0.999657 0.026177 0 0">
                                                            <inertial pos="0.0012971 -0.011934 -0.0059999"
                                                                      quat="0.489677 0.510114 -0.489692 0.510099"
                                                                      mass="0.0042405"
                                                                      diaginertia="6.9402e-07 6.62904e-07 2.10916e-07"/>
                                                            <joint name="L_ring_proximal_joint" pos="0 0 0"
                                                                   axis="0 0 -1"
                                                                   range="0 1.7" actuatorfrcrange="-1 1"/>
                                                            <geom type="mesh" contype="0" conaffinity="0" group="1"
                                                                  density="0" rgba="1 1 1 1" mesh="Link19_L"/>
                                                            <geom type="mesh" rgba="1 1 1 1" mesh="Link19_L"/>
                                                            <body name="L_ring_intermediate"
                                                                  pos="-0.0024229 -0.032041 -0.001">
                                                                <inertial pos="0.0021753 -0.019567 -0.005"
                                                                          quat="0.528694 0.469556 -0.528694 0.469556"
                                                                          mass="0.0045682"
                                                                          diaginertia="7.8176e-07 7.72437e-07 8.47208e-08"/>
                                                                <joint name="L_ring_intermediate_joint" pos="0 0 0"
                                                                       axis="0 0 -1" range="0 1.7"
                                                                       actuatorfrcrange="-1 1"/>
                                                                <geom type="mesh" contype="0" conaffinity="0" group="1"
                                                                      density="0" rgba="1 1 1 1" mesh="Link20_L"/>
                                                                <geom type="mesh" rgba="1 1 1 1" mesh="Link20_L"/>
                                                                <geom size="0.005" pos="-0.002 -0.04 -0.004" contype="0"
                                                                      conaffinity="0" group="1" density="0"
                                                                      rgba="0 1 1 1"/>
                                                            </body>
                                                        </body>
                                                        <body name="L_pinky_proximal"
                                                              pos="0.00028533 -0.13571 -0.025488"
                                                              quat="0.99863 0.0523361 0 0">
                                                            <inertial pos="0.0012971 -0.011934 -0.0059999"
                                                                      quat="0.489677 0.510114 -0.489692 0.510099"
                                                                      mass="0.0042405"
                                                                      diaginertia="6.9402e-07 6.62904e-07 2.10916e-07"/>
                                                            <joint name="L_pinky_proximal_joint" pos="0 0 0"
                                                                   axis="0 0 -1"
                                                                   range="0 1.7" actuatorfrcrange="-1 1"/>
                                                            <geom type="mesh" contype="0" conaffinity="0" group="1"
                                                                  density="0" rgba="1 1 1 1" mesh="Link21_L"/>
                                                            <geom type="mesh" rgba="1 1 1 1" mesh="Link21_L"/>
                                                            <body name="L_pinky_intermediate"
                                                                  pos="-0.0024229 -0.032041 -0.001">
                                                                <inertial pos="0.0024788 -0.016208 -0.0050001"
                                                                          quat="0.526797 0.471683 -0.526793 0.471687"
                                                                          mass="0.0036036"
                                                                          diaginertia="4.4881e-07 4.43809e-07 6.5736e-08"/>
                                                                <joint name="L_pinky_intermediate_joint" pos="0 0 0"
                                                                       axis="0 0 -1" range="0 1.7"
                                                                       actuatorfrcrange="-1 1"/>
                                                                <geom type="mesh" contype="0" conaffinity="0" group="1"
                                                                      density="0" rgba="1 1 1 1" mesh="Link22_L"/>
                                                                <geom type="mesh" rgba="1 1 1 1" mesh="Link22_L"/>
                                                                <geom size="0.005" pos="-0.002 -0.032 -0.004"
                                                                      contype="0"
                                                                      conaffinity="0" group="1" density="0"
                                                                      rgba="1 1 1 1"/>
                                                            </body>
                                                        </body>
                                                    </body>
                                                </body>
                                            </body>
                                        </body>
                                    </body>
                                </body>
                            </body>
                        </body>
                        <body name="right_shoulder_pitch_link" pos="0.0039563 -0.10021 0.23778"
                              quat="0.990264 -0.139201 1.38722e-05 9.86868e-05">
                            <inertial pos="0 -0.035892 -0.011628" quat="0.68225 -0.326267 0.0130458 0.654152"
                                      mass="0.718" diaginertia="0.000465864 0.000432842 0.000406394"/>
                            <joint name="right_shoulder_pitch_joint" pos="0 0 0" axis="0 1 0" range="-3.0892 2.6704"
                                   actuatorfrcrange="-25 25"/>
                            <geom type="mesh" contype="0" conaffinity="0" group="1" density="0" rgba="0.7 0.7 0.7 1"
                                  mesh="right_shoulder_pitch_link"/>
                            <geom size="0.03 0.025" pos="0 -0.04 -0.01" quat="0.707107 0 0.707107 0" type="cylinder"
                                  rgba="0.7 0.7 0.7 1"/>
                            <body name="right_shoulder_roll_link" pos="0 -0.038 -0.013831" quat="0.990268 0.139172 0 0">
                                <inertial pos="-0.000227 -0.00727 -0.063243"
                                          quat="0.712604 -0.00710317 -0.0196223 0.701256" mass="0.643"
                                          diaginertia="0.000691311 0.000618011 0.000388977"/>
                                <joint name="right_shoulder_roll_joint" pos="0 0 0" axis="1 0 0" range="-2.2515 1.5882"
                                       actuatorfrcrange="-25 25"/>
                                <geom type="mesh" contype="0" conaffinity="0" group="1" density="0" rgba="0.7 0.7 0.7 1"
                                      mesh="right_shoulder_roll_link"/>
                                <geom size="0.03 0.015" pos="-0.004 -0.006 -0.053" type="cylinder"
                                      rgba="0.7 0.7 0.7 1"/>
                                <body name="right_shoulder_yaw_link" pos="0 -0.00624 -0.1032">
                                    <inertial pos="0.010773 0.002949 -0.072009"
                                              quat="0.687134 -0.0679942 -0.0964829 0.716879" mass="0.734"
                                              diaginertia="0.00106187 0.00103217 0.000400661"/>
                                    <joint name="right_shoulder_yaw_joint" pos="0 0 0" axis="0 0 1" range="-2.618 2.618"
                                           actuatorfrcrange="-25 25"/>
                                    <geom type="mesh" contype="0" conaffinity="0" group="1" density="0"
                                          rgba="0.7 0.7 0.7 1" mesh="right_shoulder_yaw_link"/>
                                    <geom type="mesh" rgba="0.7 0.7 0.7 1" mesh="right_shoulder_yaw_link"/>
                                    <body name="right_elbow_link" pos="0.015783 0 -0.080518">
                                        <inertial pos="0.064956 -0.004454 -0.010062"
                                                  quat="0.388129 0.388821 0.636132 0.541765" mass="0.6"
                                                  diaginertia="0.000443035 0.000421612 0.000259353"/>
                                        <joint name="right_elbow_joint" pos="0 0 0" axis="0 1 0" range="-1.0472 2.0944"
                                               actuatorfrcrange="-25 25"/>
                                        <geom type="mesh" contype="0" conaffinity="0" group="1" density="0"
                                              rgba="0.7 0.7 0.7 1" mesh="right_elbow_link"/>
                                        <geom type="mesh" rgba="0.7 0.7 0.7 1" mesh="right_elbow_link"/>
                                        <body name="right_wrist_roll_link" pos="0.1 -0.00188791 -0.01">
                                            <inertial pos="0.0171394 -0.000537591 4.8864e-07"
                                                      quat="0.411667 0.575338 -0.411094 0.574906" mass="0.085445"
                                                      diaginertia="5.48211e-05 4.96646e-05 3.57798e-05"/>
                                            <joint name="right_wrist_roll_joint" pos="0 0 0" axis="1 0 0"
                                                   range="-1.97222 1.97222" actuatorfrcrange="-25 25"/>
                                            <geom type="mesh" contype="0" conaffinity="0" group="1" density="0"
                                                  rgba="0.7 0.7 0.7 1" mesh="right_wrist_roll_link"/>
                                            <geom type="mesh" rgba="0.7 0.7 0.7 1" mesh="right_wrist_roll_link"/>
                                            <body name="right_wrist_pitch_link" pos="0.038 0 0">
                                                <inertial pos="0.0229999 0.00111685 -0.00111658"
                                                          quat="0.643608 0.293036 0.661363 0.249998" mass="0.48405"
                                                          diaginertia="0.000430353 0.000429873 0.000164648"/>
                                                <joint name="right_wrist_pitch_joint" pos="0 0 0" axis="0 1 0"
                                                       range="-1.61443 1.61443" actuatorfrcrange="-5 5"/>
                                                <geom type="mesh" contype="0" conaffinity="0" group="1" density="0"
                                                      rgba="0.7 0.7 0.7 1" mesh="right_wrist_pitch_link"/>
                                                <geom type="mesh" rgba="0.7 0.7 0.7 1" mesh="right_wrist_pitch_link"/>
                                                <body name="right_wrist_yaw_link" pos="0.046 0 0">
                                                    <inertial pos="0.0708244 -0.000191745 0.00161742"
                                                              quat="0.493188 0.468078 0.526295 0.510571" mass="0.254576"
                                                              diaginertia="0.000646113 0.000559993 0.000147566"/>
                                                    <joint name="right_wrist_yaw_joint" pos="0 0 0" axis="0 0 1"
                                                           range="-1.61443 1.61443" actuatorfrcrange="-5 5"/>
                                                    <geom type="mesh" contype="0" conaffinity="0" group="1" density="0"
                                                          rgba="0.7 0.7 0.7 1" mesh="right_wrist_yaw_link"/>
                                                    <geom type="mesh" rgba="0.7 0.7 0.7 1" mesh="right_wrist_yaw_link"/>
                                                    <!--                                                    <geom pos="0.0415 -0.003 0" quat="0 0.707 -0.707 0" type="mesh" contype="0"-->
                                                    <!--                                                          conaffinity="0" group="1" density="0" rgba="0.7 0.7 0.7 1"-->
                                                    <!--                                                          mesh="R_hand_base_link"/>-->
                                                    <!--                                                    <geom pos="0.0415 -0.003 0" quat="0 0.707 -0.707 0" type="mesh"-->
                                                    <!--                                                          rgba="0.7 0.7 0.7 1" mesh="R_hand_base_link"/>-->
                                                    <body quat="0.000  0.707 -0.707  0.000" pos="0.0415 -0.003 0">
                                                        <geom type="mesh" contype="0" conaffinity="0" group="1"
                                                              density="0" rgba="1 1 1 1" mesh="R_hand_base_link"/>
                                                        <geom type="mesh" rgba="1 1 1 1" mesh="R_hand_base_link"/>
<!--                                                        <geom size="0.004 0.075" pos="0.075 0 0"-->
<!--                                                              quat="0.707105 0 -0.707108 0" type="cylinder" contype="0"-->
<!--                                                              conaffinity="0" group="1" density="0" rgba="1 0 0 1"/>-->
<!--                                                        <geom size="0.015" pos="0.15 0 0" quat="0.707105 0 -0.707108 0"-->
<!--                                                              contype="0" conaffinity="0" group="1" density="0"-->
<!--                                                              rgba="1 0 0 1"/>-->
<!--                                                        <geom size="0.004 0.075" pos="0 0.075 0"-->
<!--                                                              quat="0.707105 0.707108 0 0" type="cylinder" contype="0"-->
<!--                                                              conaffinity="0" group="1" density="0" rgba="0 1 0 1"/>-->
<!--                                                        <geom size="0.015" pos="0 0.15 0" quat="0.707105 0.707108 0 0"-->
<!--                                                              contype="0" conaffinity="0" group="1" density="0"-->
<!--                                                              rgba="0 1 0 1"/>-->
<!--                                                        <geom size="0.004 0.075" pos="0 0 0.075" type="cylinder"-->
<!--                                                              contype="0" conaffinity="0" group="1" density="0"-->
<!--                                                              rgba="0 0 1 1"/>-->
<!--                                                        <geom size="0.015" pos="0 0 0.15" contype="0" conaffinity="0"-->
<!--                                                              group="1" density="0" rgba="0 0 1 1"/>-->
                                                        <body name="R_thumb_proximal_base"
                                                              pos="-0.01696 -0.0691 -0.02045"
                                                              quat="0.499998 0.5 -0.5 0.500002">
                                                            <inertial pos="-0.0048064 0.0009382 -0.00757"
                                                                      quat="0.515015 0.680854 0.408023 0.323596"
                                                                      mass="0.0018869"
                                                                      diaginertia="8.66026e-08 6.8732e-08 4.94194e-08"/>
                                                            <joint name="R_thumb_proximal_yaw_joint" pos="0 0 0"
                                                                   axis="0 0 -1" range="-0.1 1.3"
                                                                   actuatorfrcrange="-1 1"/>
                                                            <geom type="mesh" contype="0" conaffinity="0" group="1"
                                                                  density="0" rgba="1 1 1 1" mesh="Link11_R"/>
                                                            <geom type="mesh" rgba="1 1 1 1" mesh="Link11_R"/>
                                                            <body name="R_thumb_proximal"
                                                                  pos="-0.0088099 0.010892 -0.00925"
                                                                  quat="0.0996843 0.0996847 0.700046 0.700044">
                                                                <inertial pos="0.021932 0.012785 -0.0080386"
                                                                          quat="-0.254474 0.660716 0.251893 0.659733"
                                                                          mass="0.0066075"
                                                                          diaginertia="2.78601e-06 2.43933e-06 8.64566e-07"/>
                                                                <joint name="R_thumb_proximal_pitch_joint" pos="0 0 0"
                                                                       axis="0 0 1" range="0 0.5"
                                                                       actuatorfrcrange="-1 1"/>
                                                                <geom type="mesh" contype="0" conaffinity="0" group="1"
                                                                      density="0" rgba="1 1 1 1" mesh="Link12_R"/>
                                                                <geom type="mesh" rgba="1 1 1 1" mesh="Link12_R"/>
                                                                <body name="R_thumb_intermediate"
                                                                      pos="0.04407 0.034553 -0.0008">
                                                                    <inertial pos="0.0095544 -0.0016282 -0.0071997"
                                                                              quat="0.636718 0.307389 -0.636802 0.307548"
                                                                              mass="0.0037847"
                                                                              diaginertia="4.6531e-07 4.48089e-07 2.45661e-07"/>
                                                                    <joint name="R_thumb_intermediate_joint" pos="0 0 0"
                                                                           axis="0 0 1" range="0 0.8"
                                                                           actuatorfrcrange="-1 1"/>
                                                                    <geom type="mesh" contype="0" conaffinity="0"
                                                                          group="1" density="0" rgba="1 1 1 1"
                                                                          mesh="Link13_R"/>
                                                                    <geom type="mesh" rgba="1 1 1 1" mesh="Link13_R"/>
                                                                    <body name="R_thumb_distal"
                                                                          pos="0.020248 0.010156 -0.0012">
                                                                        <inertial pos="0.0092888 0.0049529 -0.0060033"
                                                                                  quat="-0.266294 0.655967 0.262806 0.655537"
                                                                                  mass="0.0033441"
                                                                                  diaginertia="2.0026e-07 1.95247e-07 8.1593e-08"/>
                                                                        <joint name="R_thumb_distal_joint" pos="0 0 0"
                                                                               axis="0 0 1" range="0 1.2"
                                                                               actuatorfrcrange="-1 1"/>
                                                                        <geom type="mesh" contype="0" conaffinity="0"
                                                                              group="1" density="0" rgba="1 1 1 1"
                                                                              mesh="Link14_R"/>
                                                                        <geom type="mesh" rgba="1 1 1 1"
                                                                              mesh="Link14_R"/>
                                                                        <geom size="0.005" pos="0.015 0.013 -0.004"
                                                                              contype="0" conaffinity="0" group="1"
                                                                              density="0" rgba="1 0 0 1"/>
                                                                    </body>
                                                                </body>
                                                            </body>
                                                        </body>
                                                        <body name="R_index_proximal"
                                                              pos="0.00028533 -0.13653 -0.032268"
                                                              quat="0.0174454 -0.999848 0 0">
                                                            <inertial pos="0.0012259 0.011942 -0.0060001"
                                                                      quat="0.50867 0.49121 -0.508643 0.491172"
                                                                      mass="0.0042403"
                                                                      diaginertia="6.9398e-07 6.62871e-07 2.10909e-07"/>
                                                            <joint name="R_index_proximal_joint" pos="0 0 0"
                                                                   axis="0 0 1" range="0 1.7" actuatorfrcrange="-1 1"/>
                                                            <geom type="mesh" contype="0" conaffinity="0" group="1"
                                                                  density="0" rgba="1 1 1 1" mesh="Link15_R"/>
                                                            <geom type="mesh" rgba="1 1 1 1" mesh="Link15_R"/>
                                                            <body name="R_index_intermediate"
                                                                  pos="-0.0026138 0.032026 -0.001">
                                                                <inertial pos="0.0019697 0.019589 -0.005"
                                                                          quat="0.466773 0.531152 -0.466773 0.531153"
                                                                          mass="0.0045683"
                                                                          diaginertia="7.8179e-07 7.72465e-07 8.47212e-08"/>
                                                                <joint name="R_index_intermediate_joint" pos="0 0 0"
                                                                       axis="0 0 1" range="0 1.7"
                                                                       actuatorfrcrange="-1 1"/>
                                                                <geom type="mesh" contype="0" conaffinity="0" group="1"
                                                                      density="0" rgba="1 1 1 1" mesh="Link16_R"/>
                                                                <geom type="mesh" rgba="1 1 1 1" mesh="Link16_R"/>
                                                                <geom size="0.005" pos="-0.005 0.04 -0.004" contype="0"
                                                                      conaffinity="0" group="1" density="0"
                                                                      rgba="0 1 0 1"/>
                                                            </body>
                                                        </body>
                                                        <body name="R_middle_proximal" pos="0.00028533 -0.1371 -0.01295"
                                                              quat="-3.67321e-06 -1 0 0">
                                                            <inertial pos="0.001297 0.011934 -0.0060001"
                                                                      quat="0.510131 0.489693 -0.510105 0.489653"
                                                                      mass="0.0042403"
                                                                      diaginertia="6.9397e-07 6.62865e-07 2.10915e-07"/>
                                                            <joint name="R_middle_proximal_joint" pos="0 0 0"
                                                                   axis="0 0 1" range="0 1.7" actuatorfrcrange="-1 1"/>
                                                            <geom type="mesh" contype="0" conaffinity="0" group="1"
                                                                  density="0" rgba="1 1 1 1" mesh="Link17_R"/>
                                                            <geom type="mesh" rgba="1 1 1 1" mesh="Link17_R"/>
                                                            <body name="R_middle_intermediate"
                                                                  pos="-0.0024229 0.032041 -0.001">
                                                                <inertial pos="0.001921 0.020796 -0.005"
                                                                          quat="0.466148 0.531627 -0.466229 0.531705"
                                                                          mass="0.0050396"
                                                                          diaginertia="9.8384e-07 9.73279e-07 9.14014e-08"/>
                                                                <joint name="R_middle_intermediate_joint" pos="0 0 0"
                                                                       axis="0 0 1" range="0 1.7"
                                                                       actuatorfrcrange="-1 1"/>
                                                                <geom type="mesh" contype="0" conaffinity="0" group="1"
                                                                      density="0" rgba="1 1 1 1" mesh="Link18_R"/>
                                                                <geom type="mesh" rgba="1 1 1 1" mesh="Link18_R"/>
                                                                <geom size="0.005" pos="-0.005 0.045 -0.004" contype="0"
                                                                      conaffinity="0" group="1" density="0"
                                                                      rgba="0 0 1 1"/>
                                                            </body>
                                                        </body>
                                                        <body name="R_ring_proximal" pos="0.00028533 -0.13691 0.0062872"
                                                              quat="0.0261933 0.999657 0 0">
                                                            <inertial pos="0.001297 0.011934 -0.0060002"
                                                                      quat="0.510129 0.489691 -0.510107 0.489654"
                                                                      mass="0.0042403"
                                                                      diaginertia="6.9397e-07 6.62865e-07 2.10915e-07"/>
                                                            <joint name="R_ring_proximal_joint" pos="0 0 0" axis="0 0 1"
                                                                   range="0 1.7" actuatorfrcrange="-1 1"/>
                                                            <geom type="mesh" contype="0" conaffinity="0" group="1"
                                                                  density="0" rgba="1 1 1 1" mesh="Link19_R"/>
                                                            <geom type="mesh" rgba="1 1 1 1" mesh="Link19_R"/>
                                                            <body name="R_ring_intermediate"
                                                                  pos="-0.0024229 0.032041 -0.001">
                                                                <inertial pos="0.0021753 0.019567 -0.005"
                                                                          quat="0.469554 0.528695 -0.469554 0.528695"
                                                                          mass="0.0045683"
                                                                          diaginertia="7.8177e-07 7.72448e-07 8.4722e-08"/>
                                                                <joint name="R_ring_intermediate_joint" pos="0 0 0"
                                                                       axis="0 0 1" range="0 1.7"
                                                                       actuatorfrcrange="-1 1"/>
                                                                <geom type="mesh" contype="0" conaffinity="0" group="1"
                                                                      density="0" rgba="1 1 1 1" mesh="Link20_R"/>
                                                                <geom type="mesh" rgba="1 1 1 1" mesh="Link20_R"/>
                                                                <geom size="0.005" pos="-0.002 0.04 -0.004" contype="0"
                                                                      conaffinity="0" group="1" density="0"
                                                                      rgba="0 1 1 1"/>
                                                            </body>
                                                        </body>
                                                        <body name="R_pinky_proximal" pos="0.00028533 -0.13571 0.025488"
                                                              quat="0.0523224 0.99863 0 0">
                                                            <inertial pos="0.001297 0.011934 -0.0060001"
                                                                      quat="0.51013 0.489693 -0.510106 0.489653"
                                                                      mass="0.0042403"
                                                                      diaginertia="6.9397e-07 6.62865e-07 2.10915e-07"/>
                                                            <joint name="R_pinky_proximal_joint" pos="0 0 0"
                                                                   axis="0 0 1" range="0 1.7" actuatorfrcrange="-1 1"/>
                                                            <geom type="mesh" contype="0" conaffinity="0" group="1"
                                                                  density="0" rgba="1 1 1 1" mesh="Link21_R"/>
                                                            <geom type="mesh" rgba="1 1 1 1" mesh="Link21_R"/>
                                                            <body name="R_pinky_intermediate"
                                                                  pos="-0.0024229 0.032041 -0.001">
                                                                <inertial pos="0.0024748 0.016203 -0.0050031"
                                                                          quat="0.47398 0.528862 -0.469291 0.524799"
                                                                          mass="0.0035996"
                                                                          diaginertia="4.4867e-07 4.43723e-07 6.56538e-08"/>
                                                                <joint name="R_pinky_intermediate_joint" pos="0 0 0"
                                                                       axis="0 0 1" range="0 1.7"
                                                                       actuatorfrcrange="-1 1"/>
                                                                <geom type="mesh" contype="0" conaffinity="0" group="1"
                                                                      density="0" rgba="1 1 1 1" mesh="Link22_R"/>
                                                                <geom type="mesh" rgba="1 1 1 1" mesh="Link22_R"/>
                                                                <geom size="0.005" pos="-0.002 0.032 -0.004" contype="0"
                                                                      conaffinity="0" group="1" density="0"
                                                                      rgba="1 1 1 1"/>
                                                            </body>
                                                        </body>
                                                    </body>
                                                </body>
                                            </body>
                                        </body>
                                    </body>
                                </body>
                            </body>
                        </body>
                    </body>
                </body>
            </body>
        </body>
    </worldbody>

    <actuator>
        <!--左腿-->
        <motor name="left_hip_pitch_joint" joint="left_hip_pitch_joint"/>
        <motor name="left_hip_roll_joint" joint="left_hip_roll_joint"/>
        <motor name="left_hip_yaw_joint" joint="left_hip_yaw_joint"/>
        <motor name="left_knee_joint" joint="left_knee_joint"/>
        <motor name="left_ankle_pitch_joint" joint="left_ankle_pitch_joint"/>
        <motor name="left_ankle_roll_joint" joint="left_ankle_roll_joint"/>
        <!--右腿-->
        <motor name="right_hip_pitch_joint" joint="right_hip_pitch_joint"/>
        <motor name="right_hip_roll_joint" joint="right_hip_roll_joint"/>
        <motor name="right_hip_yaw_joint" joint="right_hip_yaw_joint"/>
        <motor name="right_knee_joint" joint="right_knee_joint"/>
        <motor name="right_ankle_pitch_joint" joint="right_ankle_pitch_joint"/>
        <motor name="right_ankle_roll_joint" joint="right_ankle_roll_joint"/>
        <!--躯干-->
        <motor name="waist_yaw_joint" joint="waist_yaw_joint"/>
        <motor name="waist_roll_joint" joint="waist_roll_joint"/>
        <motor name="waist_pitch_joint" joint="waist_pitch_joint"/>
        <!--左臂-->
        <motor name="left_shoulder_pitch_joint" joint="left_shoulder_pitch_joint"/>
        <motor name="left_shoulder_roll_joint" joint="left_shoulder_roll_joint"/>
        <motor name="left_shoulder_yaw_joint" joint="left_shoulder_yaw_joint"/>
        <motor name="left_elbow_joint" joint="left_elbow_joint"/>
        <motor name="left_wrist_roll_joint" joint="left_wrist_roll_joint"/>
        <motor name="left_wrist_pitch_joint" joint="left_wrist_pitch_joint"/>
        <motor name="left_wrist_yaw_joint" joint="left_wrist_yaw_joint"/>
        <!--左手-->
        <!--        <motor name="left_hand_thumb_0_joint" joint="left_hand_thumb_0_joint"/>-->
        <!--        <motor name="left_hand_thumb_1_joint" joint="left_hand_thumb_1_joint"/>-->
        <!--        <motor name="left_hand_thumb_2_joint" joint="left_hand_thumb_2_joint"/>-->
        <!--        <motor name="left_hand_index_0_joint" joint="left_hand_index_0_joint"/>-->
        <!--        <motor name="left_hand_index_1_joint" joint="left_hand_index_1_joint"/>-->
        <!--        <motor name="left_hand_middle_0_joint" joint="left_hand_middle_0_joint"/>-->
        <!--        <motor name="left_hand_middle_1_joint" joint="left_hand_middle_1_joint"/>-->
        <motor name="L_thumb_proximal_yaw_joint" joint="L_thumb_proximal_yaw_joint"/>
        <motor name="L_thumb_proximal_pitch_joint" joint="L_thumb_proximal_pitch_joint"/>
        <motor name="L_thumb_intermediate_joint" joint="L_thumb_intermediate_joint"/>
        <motor name="L_thumb_distal_joint" joint="L_thumb_distal_joint"/>
        <motor name="L_index_proximal_joint" joint="L_index_proximal_joint"/>
        <motor name="L_index_intermediate_joint" joint="L_index_intermediate_joint"/>
        <motor name="L_middle_proximal_joint" joint="L_middle_proximal_joint"/>
        <motor name="L_middle_intermediate_joint" joint="L_middle_intermediate_joint"/>
        <motor name="L_ring_proximal_joint" joint="L_ring_proximal_joint"/>
        <motor name="L_ring_intermediate_joint" joint="L_ring_intermediate_joint"/>
        <motor name="L_pinky_proximal_joint" joint="L_pinky_proximal_joint"/>
        <motor name="L_pinky_intermediate_joint" joint="L_pinky_intermediate_joint"/>
        <!--右臂-->
        <motor name="right_shoulder_pitch_joint" joint="right_shoulder_pitch_joint"/>
        <motor name="right_shoulder_roll_joint" joint="right_shoulder_roll_joint"/>
        <motor name="right_shoulder_yaw_joint" joint="right_shoulder_yaw_joint"/>
        <motor name="right_elbow_joint" joint="right_elbow_joint"/>
        <motor name="right_wrist_roll_joint" joint="right_wrist_roll_joint"/>
        <motor name="right_wrist_pitch_joint" joint="right_wrist_pitch_joint"/>
        <motor name="right_wrist_yaw_joint" joint="right_wrist_yaw_joint"/>
        <!--右手-->
        <!--        <motor name="right_hand_thumb_0_joint" joint="right_hand_thumb_0_joint"/>-->
        <!--        <motor name="right_hand_thumb_1_joint" joint="right_hand_thumb_1_joint"/>-->
        <!--        <motor name="right_hand_thumb_2_joint" joint="right_hand_thumb_2_joint"/>-->
        <!--        <motor name="right_hand_index_0_joint" joint="right_hand_index_0_joint"/>-->
        <!--        <motor name="right_hand_index_1_joint" joint="right_hand_index_1_joint"/>-->
        <!--        <motor name="right_hand_middle_0_joint" joint="right_hand_middle_0_joint"/>-->
        <!--        <motor name="right_hand_middle_1_joint" joint="right_hand_middle_1_joint"/>-->
        <motor name="R_thumb_proximal_yaw_joint" joint="R_thumb_proximal_yaw_joint"/>
        <motor name="R_thumb_proximal_pitch_joint" joint="R_thumb_proximal_pitch_joint"/>
        <motor name="R_thumb_intermediate_joint" joint="R_thumb_intermediate_joint"/>
        <motor name="R_thumb_distal_joint" joint="R_thumb_distal_joint"/>
        <motor name="R_index_proximal_joint" joint="R_index_proximal_joint"/>
        <motor name="R_index_intermediate_joint" joint="R_index_intermediate_joint"/>
        <motor name="R_middle_proximal_joint" joint="R_middle_proximal_joint"/>
        <motor name="R_middle_intermediate_joint" joint="R_middle_intermediate_joint"/>
        <motor name="R_ring_proximal_joint" joint="R_ring_proximal_joint"/>
        <motor name="R_ring_intermediate_joint" joint="R_ring_intermediate_joint"/>
        <motor name="R_pinky_proximal_joint" joint="R_pinky_proximal_joint"/>
        <motor name="R_pinky_intermediate_joint" joint="R_pinky_intermediate_joint"/>
    </actuator>

    <!--虚拟IMU的加速度、角速度-->
    <sensor>
        <gyro name="imu-torso-angular-velocity" site="imu_in_torso" noise="5e-4" cutoff="34.9"/>
        <accelerometer name="imu-torso-linear-acceleration" site="imu_in_torso" noise="1e-2" cutoff="157"/>
        <gyro name="imu-pelvis-angular-velocity" site="imu_in_pelvis" noise="5e-4" cutoff="34.9"/>
        <accelerometer name="imu-pelvis-linear-acceleration" site="imu_in_pelvis" noise="1e-2" cutoff="157"/>
    </sensor>


    <!-- setup scene -->
    <statistic center="1.0 0.7 1.0" extent="0.8"/>
    <visual>
        <headlight diffuse="0.6 0.6 0.6" ambient="0.1 0.1 0.1" specular="0.9 0.9 0.9"/>
        <rgba haze="0.15 0.25 0.35 1"/>
        <global azimuth="-140" elevation="-20"/>
    </visual>
    <asset>
        <texture type="skybox" builtin="flat" rgb1="0 0 0" rgb2="0 0 0" width="512" height="3072"/>
        <!--    <texture type="2d" name="groundplane" builtin="checker" mark="edge" rgb1="0.2 0.3 0.4" rgb2="0.1 0.2 0.3" markrgb="0.8 0.8 0.8" width="300" height="300"/>-->
        <!--    <material name="groundplane" texture="groundplane" texuniform="true" texrepeat="5 5" reflectance="0.2"/>-->
    </asset>
    <worldbody>
        <light pos="1 0 3.5" dir="0 0 -1" directional="true"/>
        <!--    <geom name="floor" size="0 0 0.05" type="plane" material="groundplane"/>-->
    </worldbody>
</mujoco>

        <!--
        right_shoulder_pitch_link (肩部俯仰)
        right_shoulder_roll_link (肩部横滚)
        right_shoulder_yaw_link (肩部偏航)
        right_elbow_link (肘部)
        right_wrist_roll_link (腕部横滚)
        right_wrist_pitch_link (腕部俯仰)
        right_wrist_yaw_link (腕部偏航)

        pos 位置信息
        axis 轴向信息
        quat 相对于其父体的旋转方向四元素
        diaginertia 三个主轴的惯性
        range 关节范围
        actuatorfrcrange 可视化事实力线

        红:X轴
        绿:Y轴
        蓝:Z轴
        -->