<mujoco model="g1_53dof scene">
    <include file="g1_53dof.xml"/>

    <statistic center="1.0 0.7 1.0" extent="0.8"/>

    <visual>
        <headlight diffuse="0.6 0.6 0.6" ambient="0.1 0.1 0.1" specular="0.9 0.9 0.9"/>
        <rgba haze="0.15 0.25 0.35 1"/>
        <global azimuth="-140" elevation="-20"/>
    </visual>

    <asset>
        <texture name="wood_tex" type="2d" builtin="flat"
                 width="500" height="500"
                 rgb1="1 1 1" rgb2="0.7 0.5 0.3"/>

        <material name="table_material" texture="wood_tex" shininess="0.2" reflectance="0.2"/>

        <material name="cabinet_material" rgba="0.6 0.4 0.2 1" shininess="0.1" reflectance="0.1"/>
        <material name="drawer_material" rgba="0.7 0.5 0.3 1" shininess="0.1" reflectance="0.1"/>

        <material name="glass_material" rgba="0.9 0.95 1 0.3" shininess="0.9" reflectance="0.8"/>

        <!--        <texture type="skybox" builtin="flat" rgb1="0 0 0" rgb2="0 0 0" width="512" height="3072"/>-->
        <!--        <texture type="2d" name="groundplane" builtin="checker" mark="edge" rgb1="0.2 0.3 0.4" rgb2="0.1 0.2 0.3"-->
        <!--                 markrgb="0.8 0.8 0.8" width="300" height="300"/>-->
        <!--        <material name="groundplane" texture="groundplane" texuniform="true" texrepeat="1 1" reflectance="0.2"/>-->

        <texture type="skybox" builtin="flat" rgb1="0 0 0" rgb2="0 0 0" width="512" height="3072"/>
        <texture type="2d" name="groundplane" builtin="checker" mark="edge" rgb1="0.2 0.3 0.4" rgb2="0.1 0.2 0.3"
                 markrgb="0.8 0.8 0.8" width="300" height="300"/>
        <material name="groundplane" texture="groundplane" texuniform="true" texrepeat="5 5" reflectance="0.2"/>
    </asset>

    <worldbody>
        <light pos="1 0 3.5" dir="0 0 -1" directional="true"/>
        <geom name="floor" size="0 0 0.05" type="plane" material="groundplane"/>

        <body name="box1" pos="1.20 -1.65 0.87">
            <!--qpos 广义位置会增加7个 平移位置(x,y,z)和旋转位置4元数(w,x,y,z)-->
            <!--qvel 广义速度会增加6个 3线速度（平移速度） + 3角速度(旋转速度)-->
            <freejoint/>
            <geom name="box1_wall"
                  type="box"
                  size="0.024 0.024 0.090"
                  rgba="0.1 0.9 0.1 1"
                  mass="0.014"
                  condim="4"
                  friction="1 1 1"
                  solimp="1 1 1"
                  solref="0.00001 1"
                  contype="1"
                  conaffinity="1"/>
        </body>

        <body name="box2" pos="1.20 -1.45 0.87">
            <freejoint/>
            <geom name="box1_wall2"
                  type="box"
                  size="0.024 0.024 0.090"
                  rgba="0.1 0.5 0.6 1"
                  mass="0.014"
                  condim="4"
                  friction="1 1 1"
                  solimp="1 1 1"
                  solref="0.00001 1"
                  contype="1"
                  conaffinity="1"/>
        </body>

        <body name="cup" pos="1.48 -1.41 0.87">
<!--            <freejoint/>-->
            <inertial pos="0 0 -0.03" mass="5.0" diaginertia="0.1 0.1 0.05"/>

            <geom name="cup_wall"
                  type="cylinder"
                  size="0.054 0.0625"
                  rgba="0.3 0.8 0.9 1"
                  mass="0.5"
                  contype="1"
                  conaffinity="1"/>

            <geom name="cup_bottom"
                  type="cylinder"
                  size="0.05 0.01"
                  pos="0 0 -0.05"
                  rgba="0.3 0.8 0.9 1"
                  mass="4.0"
                  contype="1"
                  conaffinity="1"/>

            <geom name="cup_handle"
                  type="capsule"
                  fromto="0.044 0 0.02 0.044 0 -0.02"
                  size="0.004"
                  rgba="0.3 0.8 0.9 1"
                  mass="0.3"
                  contype="1"
                  conaffinity="1"/>

            <geom name="cup_inner"
                  type="cylinder"
                  size="0.042 0.042"
                  pos="0 0 0"
                  rgba="1 1 1 1"
                  contype="0"
                  conaffinity="0"/>
        </body>

        <body name="cabinet1" pos="1.6 0 0.35">
            <geom name="cabinet_body1" type="box" size="0.55 5.45 0.38" material="cabinet_material"
                  contype="1" conaffinity="1"/>
            <body name="drawer1" pos="0 0 0.1">
                <joint name="drawer_slide1" type="slide" axis="0 1 0" range="-0.8 0"
                       damping="5" armature="0.1"/>
                <geom name="drawer_body1" type="box" size="0.5 1.3 0.08" material="drawer_material"
                      contype="1" conaffinity="1"/>
            </body>
        </body>

        <body name="cabinet2" pos="-1.6 0 0.35">
            <geom name="cabinet_body2" type="box" size="0.55 5.45 0.38" material="cabinet_material"
                  contype="1" conaffinity="1"/>
            <body name="drawer2" pos="0 0 0.1">
                <joint name="drawer_slide2" type="slide" axis="0 1 0" range="-0.8 0"
                       damping="5" armature="0.1"/>
                <geom name="drawer_body2" type="box" size="0.5 1.3 0.08" material="drawer_material"
                      contype="1" conaffinity="1"/>
            </body>
        </body>

        <body name="glass_panel" pos="1.85 -1.41 1.1">
            <freejoint/>
            <!-- 主玻璃板 -->
            <geom name="glass_main"
                  type="box"
                  size="0.01 0.7 0.35"
                  material="glass_material"
                  contype="1"
                  conaffinity="1"/>

            <!-- 左侧圆形洞 -->
            <geom name="hole1"
                  type="cylinder"
                  size="0.1 0.01"
                  pos="0 -0.2 0"
                  euler="0 1.5708 0"
                  rgba="0 0 0 1"
                  density="5000"
                  contype="0"
                  conaffinity="0"/>

            <!-- 右侧圆形洞 -->
            <geom name="hole2"
                  type="cylinder"
                  size="0.1 0.01"
                  pos="0 0.2 0"
                  euler="0 1.5708 0"
                  rgba="0 0 0 1"
                  density="5000"
                  contype="0"
                  conaffinity="0"/>
        </body>

        <geom name="tabletop"
              type="box"
              size="0.6 1.4 0.03"
              pos="1.6 1.41 0.75"
              rgba="0.98 0.95 0.8 1"
              material="table_material"
              contype="1"
              conaffinity="1"/>

        <geom name="tabletop2"
              type="box"
              size="0.6 1.4 0.03"
              pos="-1.6 1.41 0.75"
              rgba="0.98 0.95 0.8 1"
              material="table_material"
              contype="1"
              conaffinity="1"/>


        <geom name="tabletop3"
              type="box"
              size="0.6 1.4 0.03"
              pos="1.6 4.22 0.75"
              rgba="0.98 0.95 0.8 1"
              material="table_material"
              contype="1"
              conaffinity="1"/>

        <geom name="tabletop4"
              type="box"
              size="0.6 1.4 0.03"
              pos="-1.6 4.22 0.75"
              rgba="0.98 0.95 0.8 1"
              material="table_material"
              contype="1"
              conaffinity="1"/>

        <geom name="tabletop5"
              type="box"
              size="0.6 1.4 0.03"
              pos="1.6 -1.41 0.75"
              rgba="0.98 0.95 0.8 1"
              material="table_material"
              contype="1"
              conaffinity="1"/>

        <geom name="tabletop6"
              type="box"
              size="0.6 1.4 0.03"
              pos="-1.6 -1.41 0.75"
              rgba="0.98 0.95 0.8 1"
              material="table_material"
              contype="1"
              conaffinity="1"/>

        <geom name="tabletop7"
              type="box"
              size="0.6 1.4 0.03"
              pos="1.6 -4.22 0.75"
              rgba="0.98 0.95 0.8 1"
              material="table_material"
              contype="1"
              conaffinity="1"/>

        <geom name="tabletop8"
              type="box"
              size="0.6 1.4 0.03"
              pos="-1.6 -4.22 0.75"
              rgba="0.98 0.95 0.8 1"
              material="table_material"
              contype="1"
              conaffinity="1"/>

    </worldbody>
</mujoco>

<!-- 欧拉角定义 x横滚角(滚转角)roll y俯仰角pitch z偏航角yaw -->